<robot name="hexo" version="1.0">
  <joint name="leg1_link1_joint" type="revolute">
    <limit lower="-2.000000" upper="2.000000" effort="1.960000" velocity="5.220000"/>
    <origin rpy="0.000000 0.000000 -0.523598" xyz="0.077942 -0.045000 0.024150"/>
    <parent link="base_link"/>
    <child link="leg1_link1"/>
    <axis xyz="0.000000 0.000000 1.000000"/>
  </joint>
  <joint name="leg1_link2_joint" type="revolute">
    <limit lower="-2.000000" upper="2.000000" effort="1.960000" velocity="0.000000"/>
    <origin rpy="0.000000 0.000000 -0.000000" xyz="0.070590 -0.000900 0.000072"/>
    <parent link="leg1_link1"/>
    <child link="leg1_link2"/>
    <axis xyz="0.000000 -1.000000 0.000000"/>
  </joint>
  <joint name="leg1_link3_joint" type="revolute">
    <limit lower="-2.000000" upper="2.000000" effort="1.960000" velocity="0.000000"/>
    <origin rpy="0.000000 0.000000 0.000000" xyz="0.079450 -0.000900 -0.000072"/>
    <parent link="leg1_link2"/>
    <child link="leg1_link3"/>
    <axis xyz="0.000000 -1.000000 0.000000"/>
  </joint>
  <joint name="leg1_link4_joint" type="revolute">
    <limit lower="-3.140000" upper="3.140000" effort="10.000000" velocity="10.000000"/>
    <origin rpy="0.000000 0.000000 0.000000" xyz="0.033000 -0.000000 -0.100000"/>
    <parent link="leg1_link3"/>
    <child link="leg1_link4"/>
    <axis xyz="0.000000 0.000000 1.000000"/>
  </joint>
  <joint name="leg2_link1_joint" type="revolute">
    <limit lower="-2.000000" upper="2.000000" effort="1.960000" velocity="5.220000"/>
    <origin rpy="0.000000 0.000000 -1.570796" xyz="0.000000 -0.089999 0.024150"/>
    <parent link="base_link"/>
    <child link="leg2_link1"/>
    <axis xyz="0.000000 0.000000 1.000000"/>
  </joint>
  <joint name="leg2_link2_joint" type="revolute">
    <limit lower="-2.000000" upper="2.000000" effort="1.960000" velocity="0.000000"/>
    <origin rpy="0.000000 0.000000 0.000000" xyz="0.070590 -0.000900 0.000072"/>
    <parent link="leg2_link1"/>
    <child link="leg2_link2"/>
    <axis xyz="0.000000 -1.000000 0.000000"/>
  </joint>
  <joint name="leg2_link3_joint" type="revolute">
    <limit lower="-2.000000" upper="2.000000" effort="1.960000" velocity="0.000000"/>
    <origin rpy="0.000000 0.000000 0.000000" xyz="0.079450 -0.000900 -0.000072"/>
    <parent link="leg2_link2"/>
    <child link="leg2_link3"/>
    <axis xyz="0.000000 -1.000000 0.000000"/>
  </joint>
  <joint name="leg2_link4_joint" type="revolute">
    <limit lower="-3.140000" upper="3.140000" effort="10.000000" velocity="10.000000"/>
    <origin rpy="0.000000 0.000000 -0.000000" xyz="0.033000 -0.000000 -0.100000"/>
    <parent link="leg2_link3"/>
    <child link="leg2_link4"/>
    <axis xyz="0.000000 0.000000 1.000000"/>
  </joint>
  <joint name="leg3_link1_joint" type="revolute">
    <limit lower="-2.000000" upper="2.000000" effort="1.960000" velocity="5.220000"/>
    <origin rpy="0.000000 0.000000 -2.617994" xyz="-0.077942 -0.045000 0.024150"/>
    <parent link="base_link"/>
    <child link="leg3_link1"/>
    <axis xyz="0.000000 0.000000 1.000000"/>
  </joint>
  <joint name="leg3_link2_joint" type="revolute">
    <limit lower="-2.000000" upper="2.000000" effort="1.960000" velocity="0.000000"/>
    <origin rpy="0.000000 0.000000 0.000000" xyz="0.070590 -0.000900 0.000072"/>
    <parent link="leg3_link1"/>
    <child link="leg3_link2"/>
    <axis xyz="0.000000 -1.000000 0.000000"/>
  </joint>
  <joint name="leg3_link3_joint" type="revolute">
    <limit lower="-2.000000" upper="2.000000" effort="1.960000" velocity="0.000000"/>
    <origin rpy="0.000000 0.000000 0.000000" xyz="0.079450 -0.000900 -0.000072"/>
    <parent link="leg3_link2"/>
    <child link="leg3_link3"/>
    <axis xyz="0.000000 -1.000000 0.000000"/>
  </joint>
  <joint name="leg3_link4_joint" type="revolute">
    <limit lower="-3.140000" upper="3.140000" effort="10.000000" velocity="10.000000"/>
    <origin rpy="0.000000 0.000000 0.000000" xyz="0.033000 -0.000000 -0.100000"/>
    <parent link="leg3_link3"/>
    <child link="leg3_link4"/>
    <axis xyz="0.000000 0.000000 1.000000"/>
  </joint>
  <joint name="leg4_link1_joint" type="revolute">
    <limit lower="-2.000000" upper="2.000000" effort="1.960000" velocity="5.220000"/>
    <origin rpy="0.000000 0.000000 2.617994" xyz="-0.077942 0.045000 0.024150"/>
    <parent link="base_link"/>
    <child link="leg4_link1"/>
    <axis xyz="0.000000 0.000000 1.000000"/>
  </joint>
  <joint name="leg4_link2_joint" type="revolute">
    <limit lower="-2.000000" upper="2.000000" effort="1.960000" velocity="0.000000"/>
    <origin rpy="0.000000 0.000000 -0.000000" xyz="0.070590 -0.000900 0.000072"/>
    <parent link="leg4_link1"/>
    <child link="leg4_link2"/>
    <axis xyz="0.000000 -1.000000 0.000000"/>
  </joint>
  <joint name="leg4_link3_joint" type="revolute">
    <limit lower="-2.000000" upper="2.000000" effort="1.960000" velocity="0.000000"/>
    <origin rpy="0.000000 0.000000 -0.000000" xyz="0.079450 -0.000900 -0.000072"/>
    <parent link="leg4_link2"/>
    <child link="leg4_link3"/>
    <axis xyz="0.000000 -1.000000 0.000000"/>
  </joint>
  <joint name="leg4_link4_joint" type="revolute">
    <limit lower="-3.140000" upper="3.140000" effort="10.000000" velocity="10.000000"/>
    <origin rpy="0.000000 0.000000 -0.000000" xyz="0.033000 0.000000 -0.100000"/>
    <parent link="leg4_link3"/>
    <child link="leg4_link4"/>
    <axis xyz="0.000000 0.000000 1.000000"/>
  </joint>
  <joint name="leg5_link1_joint" type="revolute">
    <limit lower="-2.000000" upper="2.000000" effort="1.960000" velocity="5.220000"/>
    <origin rpy="0.000000 0.000000 1.570796" xyz="-0.000000 0.089999 0.024150"/>
    <parent link="base_link"/>
    <child link="leg5_link1"/>
    <axis xyz="0.000000 0.000000 1.000000"/>
  </joint>
  <joint name="leg5_link2_joint" type="revolute">
    <limit lower="-2.000000" upper="2.000000" effort="1.960000" velocity="0.000000"/>
    <origin rpy="0.000000 0.000000 -0.000000" xyz="0.070590 -0.000900 0.000072"/>
    <parent link="leg5_link1"/>
    <child link="leg5_link2"/>
    <axis xyz="0.000000 -1.000000 0.000000"/>
  </joint>
  <joint name="leg5_link3_joint" type="revolute">
    <limit lower="-2.000000" upper="2.000000" effort="1.960000" velocity="0.000000"/>
    <origin rpy="0.000000 0.000000 0.000000" xyz="0.079450 -0.000900 -0.000072"/>
    <parent link="leg5_link2"/>
    <child link="leg5_link3"/>
    <axis xyz="0.000000 -1.000000 0.000000"/>
  </joint>
  <joint name="leg5_link4_joint" type="revolute">
    <limit lower="-3.140000" upper="3.140000" effort="10.000000" velocity="10.000000"/>
    <origin rpy="0.000000 0.000000 0.000000" xyz="0.033000 -0.000000 -0.100000"/>
    <parent link="leg5_link3"/>
    <child link="leg5_link4"/>
    <axis xyz="0.000000 0.000000 1.000000"/>
  </joint>
  <joint name="leg6_link1_joint" type="revolute">
    <limit lower="-2.000000" upper="2.000000" effort="1.960000" velocity="5.220000"/>
    <origin rpy="0.000000 0.000000 0.523599" xyz="0.077942 0.045000 0.024150"/>
    <parent link="base_link"/>
    <child link="leg6_link1"/>
    <axis xyz="0.000000 0.000000 1.000000"/>
  </joint>
  <joint name="leg6_link2_joint" type="revolute">
    <limit lower="-2.000000" upper="2.000000" effort="1.960000" velocity="0.000000"/>
    <origin rpy="0.000000 0.000000 0.000000" xyz="0.070590 -0.000900 0.000072"/>
    <parent link="leg6_link1"/>
    <child link="leg6_link2"/>
    <axis xyz="0.000000 -1.000000 0.000000"/>
  </joint>
  <joint name="leg6_link3_joint" type="revolute">
    <limit lower="-2.000000" upper="2.000000" effort="1.960000" velocity="0.000000"/>
    <origin rpy="0.000000 0.000000 -0.000000" xyz="0.079450 -0.000900 -0.000072"/>
    <parent link="leg6_link2"/>
    <child link="leg6_link3"/>
    <axis xyz="0.000000 -1.000000 0.000000"/>
  </joint>
  <joint name="leg6_link4_joint" type="revolute">
    <limit lower="-3.140000" upper="3.140000" effort="10.000000" velocity="10.000000"/>
    <origin rpy="0.000000 0.000000 -0.000000" xyz="0.033000 -0.000000 -0.100000"/>
    <parent link="leg6_link3"/>
    <child link="leg6_link4"/>
    <axis xyz="0.000000 0.000000 1.000000"/>
  </joint>
  <joint name="lidar_joint" type="fixed">
    <origin rpy="0.000000 0.000000 0.000000" xyz="-0.000038 -0.000818 0.108350"/>
    <parent link="base_link"/>
    <child link="lidar_link"/>
  </joint>
  <joint name="rgbd_joint" type="fixed">
    <origin rpy="0.000000 0.000000 0.000000" xyz="0.080951 0.000000 0.084500"/>
    <parent link="base_link"/>
    <child link="rgbd_link"/>
  </joint>
  <link name="base_link">
    <inertial>
      <inertia ixx="0.000010" ixy="0.000000" ixz="0.000000" iyy="0.000010" iyz="0.000000" izz="0.000010"/>
      <origin rpy="0.000000 0.000000 0.000000" xyz="0.000000 0.000000 0.000000"/>
      <mass value="0.000010"/>
    </inertial>
    <visual name="hexo_base_v1.001">
      <origin rpy="0.000000 0.000000 0.000000" xyz="0.000000 0.000000 0.000000"/>
      <material name="Material"/>
      <geometry>
        <mesh filename="package://hexa_description/meshes/stl/hexo_base_v1.001.stl" scale="1.000000 1.000000 1.000000"/>
      </geometry>
    </visual>
  </link>
  <link name="leg1_link1">
    <inertial>
      <inertia ixx="0.000010" ixy="0.000000" ixz="0.000000" iyy="0.000010" iyz="0.000000" izz="0.000010"/>
      <origin rpy="0.000000 0.000000 0.000000" xyz="0.000000 0.000000 0.000000"/>
      <mass value="0.000010"/>
    </inertial>
    <visual name="leg5_link1.003">
      <origin rpy="0.000000 0.000000 1.570796" xyz="-0.000000 0.000000 0.000000"/>
      <material name="Material"/>
      <geometry>
        <mesh filename="package://hexa_description/meshes/stl/hexo_full.007.stl" scale="1.000000 1.000000 1.000000"/>
      </geometry>
    </visual>
  </link>
  <link name="leg1_link2">
    <inertial>
      <inertia ixx="0.000010" ixy="0.000000" ixz="0.000000" iyy="0.000010" iyz="0.000000" izz="0.000010"/>
      <origin rpy="0.000000 0.000000 0.000000" xyz="0.000000 0.000000 0.000000"/>
      <mass value="0.000010"/>
    </inertial>
    <visual name="leg5_link2.003">
      <origin rpy="0.000000 0.000000 1.570796" xyz="-0.000000 0.000000 0.000000"/>
      <material name="Material"/>
      <geometry>
        <mesh filename="package://hexa_description/meshes/stl/hexo_full.008.stl" scale="1.000000 1.000000 1.000000"/>
      </geometry>
    </visual>
  </link>
  <link name="leg1_link3">
    <inertial>
      <inertia ixx="0.000010" ixy="0.000000" ixz="0.000000" iyy="0.000010" iyz="0.000000" izz="0.000010"/>
      <origin rpy="0.000000 0.000000 0.000000" xyz="0.000000 0.000000 0.000000"/>
      <mass value="0.000010"/>
    </inertial>
    <visual name="leg5_link3.003">
      <origin rpy="0.000000 0.000000 1.570796" xyz="0.000000 -0.000000 0.000000"/>
      <material name="Material"/>
      <geometry>
        <mesh filename="package://hexa_description/meshes/stl/hexo_full.009.stl" scale="1.000000 1.000000 1.000000"/>
      </geometry>
    </visual>
  </link>
  <link name="leg1_link4">
    <inertial>
      <inertia ixx="0.000010" ixy="0.000000" ixz="0.000000" iyy="0.000010" iyz="0.000000" izz="0.000010"/>
      <origin rpy="0.000000 0.000000 0.000000" xyz="0.000000 0.000000 0.000000"/>
      <mass value="0.000010"/>
    </inertial>
  </link>
  <link name="leg2_link1">
    <inertial>
      <inertia ixx="0.000010" ixy="0.000000" ixz="0.000000" iyy="0.000010" iyz="0.000000" izz="0.000010"/>
      <origin rpy="0.000000 0.000000 0.000000" xyz="0.000000 0.000000 0.000000"/>
      <mass value="0.000010"/>
    </inertial>
    <visual name="leg5_link1.002">
      <origin rpy="0.000000 0.000000 1.570796" xyz="-0.000000 -0.000000 -0.000000"/>
      <material name="Material"/>
      <geometry>
        <mesh filename="package://hexa_description/meshes/stl/hexo_full.004.stl" scale="1.000000 1.000000 1.000000"/>
      </geometry>
    </visual>
  </link>
  <link name="leg2_link2">
    <inertial>
      <inertia ixx="0.000010" ixy="0.000000" ixz="0.000000" iyy="0.000010" iyz="0.000000" izz="0.000010"/>
      <origin rpy="0.000000 0.000000 0.000000" xyz="0.000000 0.000000 0.000000"/>
      <mass value="0.000010"/>
    </inertial>
    <visual name="leg5_link2.002">
      <origin rpy="0.000000 0.000000 1.570796" xyz="0.000000 0.000000 -0.000000"/>
      <material name="Material"/>
      <geometry>
        <mesh filename="package://hexa_description/meshes/stl/hexo_full.005.stl" scale="1.000000 1.000000 1.000000"/>
      </geometry>
    </visual>
  </link>
  <link name="leg2_link3">
    <inertial>
      <inertia ixx="0.000010" ixy="0.000000" ixz="0.000000" iyy="0.000010" iyz="0.000000" izz="0.000010"/>
      <origin rpy="0.000000 0.000000 0.000000" xyz="0.000000 0.000000 0.000000"/>
      <mass value="0.000010"/>
    </inertial>
    <visual name="leg5_link3.002">
      <origin rpy="0.000000 0.000000 1.570796" xyz="-0.000000 0.000000 -0.000000"/>
      <material name="Material"/>
      <geometry>
        <mesh filename="package://hexa_description/meshes/stl/hexo_full.006.stl" scale="1.000000 1.000000 1.000000"/>
      </geometry>
    </visual>
  </link>
  <link name="leg2_link4">
    <inertial>
      <inertia ixx="0.000010" ixy="0.000000" ixz="0.000000" iyy="0.000010" iyz="0.000000" izz="0.000010"/>
      <origin rpy="0.000000 0.000000 0.000000" xyz="0.000000 0.000000 0.000000"/>
      <mass value="0.000010"/>
    </inertial>
  </link>
  <link name="leg3_link1">
    <inertial>
      <inertia ixx="0.000010" ixy="0.000000" ixz="0.000000" iyy="0.000010" iyz="0.000000" izz="0.000010"/>
      <origin rpy="0.000000 0.000000 0.000000" xyz="0.000000 0.000000 0.000000"/>
      <mass value="0.000010"/>
    </inertial>
    <visual name="leg5_link1.006">
      <origin rpy="0.000000 0.000000 1.570797" xyz="0.000000 -0.000000 -0.000000"/>
      <material name="Material"/>
      <geometry>
        <mesh filename="package://hexa_description/meshes/stl/hexo_full.019.stl" scale="1.000000 1.000000 1.000000"/>
      </geometry>
    </visual>
  </link>
  <link name="leg3_link2">
    <inertial>
      <inertia ixx="0.000010" ixy="0.000000" ixz="0.000000" iyy="0.000010" iyz="0.000000" izz="0.000010"/>
      <origin rpy="0.000000 0.000000 0.000000" xyz="0.000000 0.000000 0.000000"/>
      <mass value="0.000010"/>
    </inertial>
    <visual name="leg5_link2.006">
      <origin rpy="0.000000 0.000000 1.570797" xyz="0.000000 0.000000 0.000000"/>
      <material name="Material"/>
      <geometry>
        <mesh filename="package://hexa_description/meshes/stl/hexo_full.020.stl" scale="1.000000 1.000000 1.000000"/>
      </geometry>
    </visual>
  </link>
  <link name="leg3_link3">
    <inertial>
      <inertia ixx="0.000010" ixy="0.000000" ixz="0.000000" iyy="0.000010" iyz="0.000000" izz="0.000010"/>
      <origin rpy="0.000000 0.000000 0.000000" xyz="0.000000 0.000000 0.000000"/>
      <mass value="0.000010"/>
    </inertial>
    <visual name="leg5_link3.006">
      <origin rpy="0.000000 0.000000 1.570797" xyz="-0.000000 0.000000 0.000000"/>
      <material name="Material"/>
      <geometry>
        <mesh filename="package://hexa_description/meshes/stl/hexo_full.021.stl" scale="1.000000 1.000000 1.000000"/>
      </geometry>
    </visual>
  </link>
  <link name="leg3_link4">
    <inertial>
      <inertia ixx="0.000010" ixy="0.000000" ixz="0.000000" iyy="0.000010" iyz="0.000000" izz="0.000010"/>
      <origin rpy="0.000000 0.000000 0.000000" xyz="0.000000 0.000000 0.000000"/>
      <mass value="0.000010"/>
    </inertial>
  </link>
  <link name="leg4_link1">
    <inertial>
      <inertia ixx="0.000010" ixy="0.000000" ixz="0.000000" iyy="0.000010" iyz="0.000000" izz="0.000010"/>
      <origin rpy="0.000000 0.000000 0.000000" xyz="0.000000 0.000000 0.000000"/>
      <mass value="0.000010"/>
    </inertial>
    <visual name="leg5_link1.005">
      <origin rpy="0.000000 0.000000 1.570797" xyz="0.000000 -0.000000 -0.000000"/>
      <material name="Material"/>
      <geometry>
        <mesh filename="package://hexa_description/meshes/stl/hexo_full.016.stl" scale="1.000000 1.000000 1.000000"/>
      </geometry>
    </visual>
  </link>
  <link name="leg4_link2">
    <inertial>
      <inertia ixx="0.000010" ixy="0.000000" ixz="0.000000" iyy="0.000010" iyz="0.000000" izz="0.000010"/>
      <origin rpy="0.000000 0.000000 0.000000" xyz="0.000000 0.000000 0.000000"/>
      <mass value="0.000010"/>
    </inertial>
    <visual name="leg5_link2.005">
      <origin rpy="0.000000 0.000000 1.570797" xyz="0.000000 -0.000000 0.000000"/>
      <material name="Material"/>
      <geometry>
        <mesh filename="package://hexa_description/meshes/stl/hexo_full.017.stl" scale="1.000000 1.000000 1.000000"/>
      </geometry>
    </visual>
  </link>
  <link name="leg4_link3">
    <inertial>
      <inertia ixx="0.000010" ixy="0.000000" ixz="0.000000" iyy="0.000010" iyz="0.000000" izz="0.000010"/>
      <origin rpy="0.000000 0.000000 0.000000" xyz="0.000000 0.000000 0.000000"/>
      <mass value="0.000010"/>
    </inertial>
    <visual name="leg5_link3.005">
      <origin rpy="0.000000 0.000000 1.570797" xyz="-0.000000 -0.000000 0.000000"/>
      <material name="Material"/>
      <geometry>
        <mesh filename="package://hexa_description/meshes/stl/hexo_full.022.stl" scale="1.000000 1.000000 1.000000"/>
      </geometry>
    </visual>
  </link>
  <link name="leg4_link4">
    <inertial>
      <inertia ixx="0.000010" ixy="0.000000" ixz="0.000000" iyy="0.000010" iyz="0.000000" izz="0.000010"/>
      <origin rpy="0.000000 0.000000 0.000000" xyz="0.000000 0.000000 0.000000"/>
      <mass value="0.000010"/>
    </inertial>
  </link>
  <link name="leg5_link1">
    <inertial>
      <inertia ixx="0.000010" ixy="0.000000" ixz="0.000000" iyy="0.000010" iyz="0.000000" izz="0.000010"/>
      <origin rpy="0.000000 0.000000 0.000000" xyz="0.000000 0.000000 0.000000"/>
      <mass value="0.000010"/>
    </inertial>
    <visual name="leg5_link1.004">
      <origin rpy="0.000000 0.000000 1.570797" xyz="0.000000 -0.000000 -0.000000"/>
      <material name="Material"/>
      <geometry>
        <mesh filename="package://hexa_description/meshes/stl/hexo_full.013.stl" scale="1.000000 1.000000 1.000000"/>
      </geometry>
    </visual>
  </link>
  <link name="leg5_link2">
    <inertial>
      <inertia ixx="0.000010" ixy="0.000000" ixz="0.000000" iyy="0.000010" iyz="0.000000" izz="0.000010"/>
      <origin rpy="0.000000 0.000000 0.000000" xyz="0.000000 0.000000 0.000000"/>
      <mass value="0.000010"/>
    </inertial>
    <visual name="leg5_link2.004">
      <origin rpy="0.000000 0.000000 1.570797" xyz="-0.000000 0.000000 0.000000"/>
      <material name="Material"/>
      <geometry>
        <mesh filename="package://hexa_description/meshes/stl/hexo_full.014.stl" scale="1.000000 1.000000 1.000000"/>
      </geometry>
    </visual>
  </link>
  <link name="leg5_link3">
    <inertial>
      <inertia ixx="0.000010" ixy="0.000000" ixz="0.000000" iyy="0.000010" iyz="0.000000" izz="0.000010"/>
      <origin rpy="0.000000 0.000000 0.000000" xyz="0.000000 0.000000 0.000000"/>
      <mass value="0.000010"/>
    </inertial>
    <visual name="leg5_link3.004">
      <origin rpy="0.000000 0.000000 1.570797" xyz="-0.000000 0.000000 0.000000"/>
      <material name="Material"/>
      <geometry>
        <mesh filename="package://hexa_description/meshes/stl/hexo_full.015.stl" scale="1.000000 1.000000 1.000000"/>
      </geometry>
    </visual>
  </link>
  <link name="leg5_link4">
    <inertial>
      <inertia ixx="0.000010" ixy="0.000000" ixz="0.000000" iyy="0.000010" iyz="0.000000" izz="0.000010"/>
      <origin rpy="0.000000 0.000000 0.000000" xyz="0.000000 0.000000 0.000000"/>
      <mass value="0.000010"/>
    </inertial>
  </link>
  <link name="leg6_link1">
    <inertial>
      <inertia ixx="0.000010" ixy="0.000000" ixz="0.000000" iyy="0.000010" iyz="0.000000" izz="0.000010"/>
      <origin rpy="0.000000 0.000000 0.000000" xyz="0.000000 0.000000 0.000000"/>
      <mass value="0.000010"/>
    </inertial>
    <visual name="leg5_link1.001">
      <origin rpy="0.000000 0.000000 1.570796" xyz="0.000000 -0.000000 -0.000000"/>
      <material name="Material"/>
      <geometry>
        <mesh filename="package://hexa_description/meshes/stl/hexo_full.010.stl" scale="1.000000 1.000000 1.000000"/>
      </geometry>
    </visual>
  </link>
  <link name="leg6_link2">
    <inertial>
      <inertia ixx="0.000010" ixy="0.000000" ixz="0.000000" iyy="0.000010" iyz="0.000000" izz="0.000010"/>
      <origin rpy="0.000000 0.000000 0.000000" xyz="0.000000 0.000000 0.000000"/>
      <mass value="0.000010"/>
    </inertial>
    <visual name="leg5_link2.001">
      <origin rpy="0.000000 0.000000 1.570796" xyz="0.000000 -0.000000 -0.000000"/>
      <material name="Material"/>
      <geometry>
        <mesh filename="package://hexa_description/meshes/stl/hexo_full.011.stl" scale="1.000000 1.000000 1.000000"/>
      </geometry>
    </visual>
  </link>
  <link name="leg6_link3">
    <inertial>
      <inertia ixx="0.000010" ixy="0.000000" ixz="0.000000" iyy="0.000010" iyz="0.000000" izz="0.000010"/>
      <origin rpy="0.000000 0.000000 0.000000" xyz="0.000000 0.000000 0.000000"/>
      <mass value="0.000010"/>
    </inertial>
    <visual name="leg5_link3.001">
      <origin rpy="0.000000 0.000000 1.570796" xyz="-0.000000 0.000000 -0.000000"/>
      <material name="Material"/>
      <geometry>
        <mesh filename="package://hexa_description/meshes/stl/hexo_full.012.stl" scale="1.000000 1.000000 1.000000"/>
      </geometry>
    </visual>
  </link>
  <link name="leg6_link4">
    <inertial>
      <inertia ixx="0.000010" ixy="0.000000" ixz="0.000000" iyy="0.000010" iyz="0.000000" izz="0.000010"/>
      <origin rpy="0.000000 0.000000 0.000000" xyz="0.000000 0.000000 0.000000"/>
      <mass value="0.000010"/>
    </inertial>
  </link>
  <link name="lidar_link">
    <inertial>
      <inertia ixx="0.000010" ixy="0.000000" ixz="0.000000" iyy="0.000010" iyz="0.000000" izz="0.000010"/>
      <origin rpy="0.000000 0.000000 0.000000" xyz="0.000000 0.000000 0.000000"/>
      <mass value="0.000010"/>
    </inertial>
    <visual name="hexo_base_v1.002">
      <origin rpy="0.000000 0.000000 0.000000" xyz="0.000000 0.000000 0.000000"/>
      <material name="Material"/>
      <geometry>
        <mesh filename="package://hexa_description/meshes/stl/hexo_base_v1.003.stl" scale="1.000000 1.000000 1.000000"/>
      </geometry>
    </visual>
  </link>
  <link name="rgbd_link">
    <inertial>
      <inertia ixx="0.000010" ixy="0.000000" ixz="0.000000" iyy="0.000010" iyz="0.000000" izz="0.000010"/>
      <origin rpy="0.000000 0.000000 0.000000" xyz="0.000000 0.000000 0.000000"/>
      <mass value="0.000010"/>
    </inertial>
    <visual name="hexo_base_v1">
      <origin rpy="0.000000 0.000000 0.000000" xyz="0.000000 0.000000 0.000000"/>
      <material name="Material"/>
      <geometry>
        <mesh filename="package://hexa_description/meshes/stl/hexo_base_v1.stl" scale="1.000000 1.000000 1.000000"/>
      </geometry>
    </visual>
  </link>
  <material name="Material">
    <color rgba="0.133333 0.415686 0.800000 1.000000"/>
  </material>
</robot>