<robot name="hexo" version="1.0">
  <joint name="leg1_link1_joint" type="revolute">
    <limit lower="-2.000000" upper="2.000000" effort="1.960000" velocity="5.220000"/>
    <origin rpy="0.000000 0.000000 -0.523598" xyz="0.075777 -0.043750 -0.000000"/>
    <parent link="base_link"/>
    <child link="leg1_link1"/>
    <axis xyz="0.000000 0.000000 1.000000"/>
  </joint>
  <joint name="leg1_link2_joint" type="revolute">
    <limit lower="-2.000000" upper="2.000000" effort="1.960000" velocity="0.000000"/>
    <origin rpy="0.000000 0.000000 -0.000000" xyz="0.080000 -0.000000 0.000000"/>
    <parent link="leg1_link1"/>
    <child link="leg1_link2"/>
    <axis xyz="0.000000 -1.000000 0.000000"/>
  </joint>
  <joint name="leg1_link3_joint" type="revolute">
    <limit lower="-2.000000" upper="2.000000" effort="1.960000" velocity="0.000000"/>
    <origin rpy="0.000000 0.000000 0.000000" xyz="0.080000 -0.000000 -0.000000"/>
    <parent link="leg1_link2"/>
    <child link="leg1_link3"/>
    <axis xyz="0.000000 -1.000000 0.000000"/>
  </joint>
  <joint name="leg1_link4_joint" type="revolute">
    <limit lower="-3.140000" upper="3.140000" effort="10.000000" velocity="10.000000"/>
    <origin rpy="0.000000 0.000000 0.000000" xyz="0.034000 -0.000000 -0.111000"/>
    <parent link="leg1_link3"/>
    <child link="leg1_link4"/>
    <axis xyz="0.000000 0.000000 1.000000"/>
  </joint>
  <joint name="leg2_link1_joint" type="revolute">
    <limit lower="-2.000000" upper="2.000000" effort="1.960000" velocity="5.220000"/>
    <origin rpy="0.000000 0.000000 -1.570796" xyz="0.000000 -0.087500 -0.000000"/>
    <parent link="base_link"/>
    <child link="leg2_link1"/>
    <axis xyz="0.000000 0.000000 1.000000"/>
  </joint>
  <joint name="leg2_link2_joint" type="revolute">
    <limit lower="-2.000000" upper="2.000000" effort="1.960000" velocity="0.000000"/>
    <origin rpy="0.000000 0.000000 0.000000" xyz="0.080000 -0.000000 0.000000"/>
    <parent link="leg2_link1"/>
    <child link="leg2_link2"/>
    <axis xyz="0.000000 -1.000000 0.000000"/>
  </joint>
  <joint name="leg2_link3_joint" type="revolute">
    <limit lower="-2.000000" upper="2.000000" effort="1.960000" velocity="0.000000"/>
    <origin rpy="0.000000 0.000000 0.000000" xyz="0.080000 -0.000000 0.000000"/>
    <parent link="leg2_link2"/>
    <child link="leg2_link3"/>
    <axis xyz="0.000000 -1.000000 0.000000"/>
  </joint>
  <joint name="leg2_link4_joint" type="revolute">
    <limit lower="-3.140000" upper="3.140000" effort="10.000000" velocity="10.000000"/>
    <origin rpy="0.000000 0.000000 -0.000000" xyz="0.034000 -0.000000 -0.111000"/>
    <parent link="leg2_link3"/>
    <child link="leg2_link4"/>
    <axis xyz="0.000000 0.000000 1.000000"/>
  </joint>
  <joint name="leg3_link1_joint" type="revolute">
    <limit lower="-2.000000" upper="2.000000" effort="1.960000" velocity="5.220000"/>
    <origin rpy="0.000000 0.000000 -2.617994" xyz="-0.075777 -0.043750 -0.000000"/>
    <parent link="base_link"/>
    <child link="leg3_link1"/>
    <axis xyz="0.000000 0.000000 1.000000"/>
  </joint>
  <joint name="leg3_link2_joint" type="revolute">
    <limit lower="-2.000000" upper="2.000000" effort="1.960000" velocity="0.000000"/>
    <origin rpy="0.000000 0.000000 0.000000" xyz="0.080000 -0.000000 0.000000"/>
    <parent link="leg3_link1"/>
    <child link="leg3_link2"/>
    <axis xyz="0.000000 -1.000000 0.000000"/>
  </joint>
  <joint name="leg3_link3_joint" type="revolute">
    <limit lower="-2.000000" upper="2.000000" effort="1.960000" velocity="0.000000"/>
    <origin rpy="0.000000 0.000000 0.000000" xyz="0.080000 -0.000000 0.000000"/>
    <parent link="leg3_link2"/>
    <child link="leg3_link3"/>
    <axis xyz="0.000000 -1.000000 0.000000"/>
  </joint>
  <joint name="leg3_link4_joint" type="revolute">
    <limit lower="-3.140000" upper="3.140000" effort="10.000000" velocity="10.000000"/>
    <origin rpy="0.000000 0.000000 0.000000" xyz="0.034000 -0.000000 -0.111000"/>
    <parent link="leg3_link3"/>
    <child link="leg3_link4"/>
    <axis xyz="0.000000 0.000000 1.000000"/>
  </joint>
  <joint name="leg4_link1_joint" type="revolute">
    <limit lower="-2.000000" upper="2.000000" effort="1.960000" velocity="5.220000"/>
    <origin rpy="0.000000 0.000000 2.617994" xyz="-0.075777 0.043750 -0.000000"/>
    <parent link="base_link"/>
    <child link="leg4_link1"/>
    <axis xyz="0.000000 0.000000 1.000000"/>
  </joint>
  <joint name="leg4_link2_joint" type="revolute">
    <limit lower="-2.000000" upper="2.000000" effort="1.960000" velocity="0.000000"/>
    <origin rpy="0.000000 0.000000 -0.000000" xyz="0.080000 -0.000000 0.000000"/>
    <parent link="leg4_link1"/>
    <child link="leg4_link2"/>
    <axis xyz="0.000000 -1.000000 0.000000"/>
  </joint>
  <joint name="leg4_link3_joint" type="revolute">
    <limit lower="-2.000000" upper="2.000000" effort="1.960000" velocity="0.000000"/>
    <origin rpy="0.000000 0.000000 -0.000000" xyz="0.080000 0.000000 0.000000"/>
    <parent link="leg4_link2"/>
    <child link="leg4_link3"/>
    <axis xyz="0.000000 -1.000000 0.000000"/>
  </joint>
  <joint name="leg4_link4_joint" type="revolute">
    <limit lower="-3.140000" upper="3.140000" effort="10.000000" velocity="10.000000"/>
    <origin rpy="0.000000 0.000000 -0.000000" xyz="0.034000 0.000000 -0.111000"/>
    <parent link="leg4_link3"/>
    <child link="leg4_link4"/>
    <axis xyz="0.000000 0.000000 1.000000"/>
  </joint>
  <joint name="leg5_link1_joint" type="revolute">
    <limit lower="-2.000000" upper="2.000000" effort="1.960000" velocity="5.220000"/>
    <origin rpy="0.000000 0.000000 1.570796" xyz="-0.000000 0.087500 -0.000000"/>
    <parent link="base_link"/>
    <child link="leg5_link1"/>
    <axis xyz="0.000000 0.000000 1.000000"/>
  </joint>
  <joint name="leg5_link2_joint" type="revolute">
    <limit lower="-2.000000" upper="2.000000" effort="1.960000" velocity="0.000000"/>
    <origin rpy="0.000000 0.000000 -0.000000" xyz="0.080000 -0.000000 0.000000"/>
    <parent link="leg5_link1"/>
    <child link="leg5_link2"/>
    <axis xyz="0.000000 -1.000000 0.000000"/>
  </joint>
  <joint name="leg5_link3_joint" type="revolute">
    <limit lower="-2.000000" upper="2.000000" effort="1.960000" velocity="0.000000"/>
    <origin rpy="0.000000 0.000000 0.000000" xyz="0.080000 -0.000000 -0.000000"/>
    <parent link="leg5_link2"/>
    <child link="leg5_link3"/>
    <axis xyz="0.000000 -1.000000 0.000000"/>
  </joint>
  <joint name="leg5_link4_joint" type="revolute">
    <limit lower="-3.140000" upper="3.140000" effort="10.000000" velocity="10.000000"/>
    <origin rpy="0.000000 0.000000 0.000000" xyz="0.034000 -0.000000 -0.111000"/>
    <parent link="leg5_link3"/>
    <child link="leg5_link4"/>
    <axis xyz="0.000000 0.000000 1.000000"/>
  </joint>
  <joint name="leg6_link1_joint" type="revolute">
    <limit lower="-2.000000" upper="2.000000" effort="1.960000" velocity="5.220000"/>
    <origin rpy="0.000000 0.000000 0.523599" xyz="0.075777 0.043750 -0.000000"/>
    <parent link="base_link"/>
    <child link="leg6_link1"/>
    <axis xyz="0.000000 0.000000 1.000000"/>
  </joint>
  <joint name="leg6_link2_joint" type="revolute">
    <limit lower="-2.000000" upper="2.000000" effort="1.960000" velocity="0.000000"/>
    <origin rpy="0.000000 0.000000 0.000000" xyz="0.080000 -0.000000 0.000000"/>
    <parent link="leg6_link1"/>
    <child link="leg6_link2"/>
    <axis xyz="0.000000 -1.000000 0.000000"/>
  </joint>
  <joint name="leg6_link3_joint" type="revolute">
    <limit lower="-2.000000" upper="2.000000" effort="1.960000" velocity="0.000000"/>
    <origin rpy="0.000000 0.000000 -0.000000" xyz="0.080000 -0.000000 0.000000"/>
    <parent link="leg6_link2"/>
    <child link="leg6_link3"/>
    <axis xyz="0.000000 -1.000000 0.000000"/>
  </joint>
  <joint name="leg6_link4_joint" type="revolute">
    <limit lower="-3.140000" upper="3.140000" effort="10.000000" velocity="10.000000"/>
    <origin rpy="0.000000 0.000000 -0.000000" xyz="0.034000 -0.000000 -0.111000"/>
    <parent link="leg6_link3"/>
    <child link="leg6_link4"/>
    <axis xyz="0.000000 0.000000 1.000000"/>
  </joint>
  <link name="base_link">
  
    <visual name="base">
      <origin rpy="0.000000 0.000000 0.000000" xyz="0.000000 0.000000 -0.025435"/>
      <material name="Material"/>
      <geometry>
        <mesh filename="package://hexa_description/meshes/stl/base.stl" scale="1.000000 1.000000 1.000000"/>
      </geometry>
    </visual>
  </link>
  <link name="leg1_link1">
  
    <visual name="leg5_link1.009">
      <origin rpy="0.000000 0.000000 0.000000" xyz="0.000000 0.000000 -0.025950"/>
      <material name="Material"/>
      <geometry>
        <mesh filename="package://hexa_description/meshes/stl/leg5_stl1.009.stl" scale="1.000000 1.000000 1.000000"/>
      </geometry>
    </visual>
  </link>
  <link name="leg1_link2">
  
    <visual name="leg5_link2.009">
      <origin rpy="0.000000 0.000000 0.000000" xyz="-0.000000 -0.025850 0.000000"/>
      <material name="Material"/>
      <geometry>
        <mesh filename="package://hexa_description/meshes/stl/leg5_stl2.009.stl" scale="1.000000 1.000000 1.000000"/>
      </geometry>
    </visual>
  </link>
  <link name="leg1_link3">
  
    <visual name="leg5_link3.009">
      <origin rpy="0.000000 0.000000 0.000000" xyz="-0.000000 -0.025750 0.000000"/>
      <material name="Material"/>
      <geometry>
        <mesh filename="package://hexa_description/meshes/stl/leg5_stl3.009.stl" scale="1.000000 1.000000 1.000000"/>
      </geometry>
    </visual>
  </link>
  <link name="leg1_link4">
  
  </link>
  <link name="leg2_link1">
  
    <visual name="leg5_link1.001">
      <origin rpy="0.000000 0.000000 0.000000" xyz="0.000000 0.000000 -0.025950"/>
      <material name="Material"/>
      <geometry>
        <mesh filename="package://hexa_description/meshes/stl/leg5_stl1.001.stl" scale="1.000000 1.000000 1.000000"/>
      </geometry>
    </visual>
  </link>
  <link name="leg2_link2">
  
    <visual name="leg5_link2.001">
      <origin rpy="0.000000 0.000000 0.000000" xyz="0.000000 -0.025850 0.000000"/>
      <material name="Material"/>
      <geometry>
        <mesh filename="package://hexa_description/meshes/stl/leg5_stl2.001.stl" scale="1.000000 1.000000 1.000000"/>
      </geometry>
    </visual>
  </link>
  <link name="leg2_link3">
  
    <visual name="leg5_link3.001">
      <origin rpy="0.000000 0.000000 0.000000" xyz="0.000000 -0.025750 0.000000"/>
      <material name="Material"/>
      <geometry>
        <mesh filename="package://hexa_description/meshes/stl/leg5_stl3.001.stl" scale="1.000000 1.000000 1.000000"/>
      </geometry>
    </visual>
  </link>
  <link name="leg2_link4">
  
  </link>
  <link name="leg3_link1">
  
    <visual name="leg5_link1.005">
      <origin rpy="0.000000 0.000000 -0.000000" xyz="0.000000 0.000000 -0.025950"/>
      <material name="Material"/>
      <geometry>
        <mesh filename="package://hexa_description/meshes/stl/leg5_stl1.005.stl" scale="1.000000 1.000000 1.000000"/>
      </geometry>
    </visual>
  </link>
  <link name="leg3_link2">
  
    <visual name="leg5_link2.005">
      <origin rpy="0.000000 0.000000 -0.000000" xyz="0.000000 -0.025850 0.000000"/>
      <material name="Material"/>
      <geometry>
        <mesh filename="package://hexa_description/meshes/stl/leg5_stl2.005.stl" scale="1.000000 1.000000 1.000000"/>
      </geometry>
    </visual>
  </link>
  <link name="leg3_link3">
  
    <visual name="leg5_link3.005">
      <origin rpy="0.000000 0.000000 -0.000000" xyz="-0.000000 -0.025750 0.000000"/>
      <material name="Material"/>
      <geometry>
        <mesh filename="package://hexa_description/meshes/stl/leg5_stl3.005.stl" scale="1.000000 1.000000 1.000000"/>
      </geometry>
    </visual>
  </link>
  <link name="leg3_link4">
  
  </link>
  <link name="leg4_link1">
  
    <visual name="leg5_link1.003">
      <origin rpy="0.000000 0.000000 -0.000000" xyz="0.000000 0.000000 -0.025950"/>
      <material name="Material"/>
      <geometry>
        <mesh filename="package://hexa_description/meshes/stl/leg5_stl1.003.stl" scale="1.000000 1.000000 1.000000"/>
      </geometry>
    </visual>
  </link>
  <link name="leg4_link2">
  
    <visual name="leg5_link2.003">
      <origin rpy="0.000000 0.000000 -0.000000" xyz="0.000000 -0.025850 0.000000"/>
      <material name="Material"/>
      <geometry>
        <mesh filename="package://hexa_description/meshes/stl/leg5_stl2.003.stl" scale="1.000000 1.000000 1.000000"/>
      </geometry>
    </visual>
  </link>
  <link name="leg4_link3">
  
    <visual name="leg5_link3.003">
      <origin rpy="0.000000 0.000000 -0.000000" xyz="0.000000 -0.025750 0.000000"/>
      <material name="Material"/>
      <geometry>
        <mesh filename="package://hexa_description/meshes/stl/leg5_stl3.003.stl" scale="1.000000 1.000000 1.000000"/>
      </geometry>
    </visual>
  </link>
  <link name="leg4_link4">
  
  </link>
  <link name="leg5_link1">
  
    <visual name="leg5_link1.007">
      <origin rpy="0.000000 0.000000 0.000000" xyz="0.000000 0.000000 -0.025950"/>
      <material name="Material"/>
      <geometry>
        <mesh filename="package://hexa_description/meshes/stl/leg5_stl1.007.stl" scale="1.000000 1.000000 1.000000"/>
      </geometry>
    </visual>
  </link>
  <link name="leg5_link2">
  
    <visual name="leg5_link2.007">
      <origin rpy="0.000000 0.000000 -0.000000" xyz="-0.000000 -0.025850 0.000000"/>
      <material name="Material"/>
      <geometry>
        <mesh filename="package://hexa_description/meshes/stl/leg5_stl2.007.stl" scale="1.000000 1.000000 1.000000"/>
      </geometry>
    </visual>
  </link>
  <link name="leg5_link3">
  
    <visual name="leg5_link3.007">
      <origin rpy="0.000000 0.000000 -0.000000" xyz="-0.000000 -0.025750 0.000000"/>
      <material name="Material"/>
      <geometry>
        <mesh filename="package://hexa_description/meshes/stl/leg5_stl3.007.stl" scale="1.000000 1.000000 1.000000"/>
      </geometry>
    </visual>
  </link>
  <link name="leg5_link4">
  
  </link>
  <link name="leg6_link1">
  
    <visual name="leg5_link1.011">
      <origin rpy="0.000000 0.000000 -0.000000" xyz="0.000000 -0.000000 -0.025950"/>
      <material name="Material"/>
      <geometry>
        <mesh filename="package://hexa_description/meshes/stl/leg5_stl1.011.stl" scale="1.000000 1.000000 1.000000"/>
      </geometry>
    </visual>
  </link>
  <link name="leg6_link2">
  
    <visual name="leg5_link2.011">
      <origin rpy="0.000000 0.000000 0.000000" xyz="-0.000000 -0.025850 -0.000000"/>
      <material name="Material"/>
      <geometry>
        <mesh filename="package://hexa_description/meshes/stl/leg5_stl2.011.stl" scale="1.000000 1.000000 1.000000"/>
      </geometry>
    </visual>
  </link>
  <link name="leg6_link3">
  
    <visual name="leg5_link3.011">
      <origin rpy="0.000000 0.000000 -0.000000" xyz="-0.000000 -0.025750 0.000000"/>
      <material name="Material"/>
      <geometry>
        <mesh filename="package://hexa_description/meshes/stl/leg5_stl3.011.stl" scale="1.000000 1.000000 1.000000"/>
      </geometry>
    </visual>
  </link>
  <link name="leg6_link4">
  
  </link>
  <material name="Material">
    <color rgba="0.133333 0.415686 0.800000 0.50000"/>
  </material>
</robot>